<robot name="escalador_movel" version="1.0">
  <joint name="J1" type="revolute">
    <limit lower="-3.14000" upper="3.14000" effort="0.00000" velocity="0.00000"/>
    <origin rpy="1.57080 0.00000 -3.14159" xyz="0.00004 -0.11823 0.02811"/>
    <parent link="LINK_2_visual_link"/>
    <child link="LINK_1_visual_link"/>
    <axis xyz="0.00000 0.00000 1.00000"/>
  </joint>
  <joint name="J2" type="revolute">
    <limit lower="-3.14000" upper="3.14000" effort="0.00000" velocity="0.00000"/>
    <origin rpy="0.00000 0.00000 -1.04649" xyz="-0.10207 -0.17231 -0.02796"/>
    <parent link="LINK_3_2"/>
    <child link="LINK_2_visual_link"/>
    <axis xyz="0.00000 0.00000 1.00000"/>
  </joint>
  <joint name="J3" type="revolute">
    <limit lower="-3.14000" upper="3.14000" effort="0.00000" velocity="0.00000"/>
    <origin rpy="1.57080 1.04720 -0.00000" xyz="0.00162 -0.02116 0.00162"/>
    <parent link="LINK_3_visual_link"/>
    <child link="LINK_4_visual_link"/>
    <axis xyz="0.00000 0.00000 1.00000"/>
  </joint>
  <joint name="J4" type="revolute">
    <limit lower="-3.14000" upper="3.14000" effort="0.00000" velocity="0.00000"/>
    <origin rpy="-1.57080 0.00000 0.50725" xyz="0.07277 -0.13084 -0.02010"/>
    <parent link="LINK_4_visual_link"/>
    <child link="LINK_5_visual_link"/>
    <axis xyz="0.00000 0.00000 1.00000"/>
  </joint>
  <joint name="J5" type="revolute">
    <limit lower="-3.14000" upper="3.14000" effort="0.00000" velocity="0.00000"/>
    <origin rpy="1.57080 -0.52360 0.00000" xyz="0.00005 -0.01886 -0.05053"/>
    <parent link="LINK_5_visual_link"/>
    <child link="LINK_6_visual_link"/>
    <axis xyz="0.00000 0.00000 1.00000"/>
  </joint>
  <joint name="J6" type="revolute">
    <limit lower="-3.14000" upper="3.14000" effort="0.00000" velocity="0.00000"/>
    <origin rpy="1.57080 0.00000 3.14159" xyz="0.00004 -0.11898 -0.02009"/>
    <parent link="LINK_6_visual_link"/>
    <child link="LINK_7_visual_link"/>
    <axis xyz="0.00000 0.00000 1.00000"/>
  </joint>
  <joint name="j3_2" type="revolute">
    <limit lower="-3.14000" upper="3.14000" effort="0.00000" velocity="0.00000"/>
    <origin rpy="1.57079 -1.04649 0.00000" xyz="0.00162 0.00016 0.00162"/>
    <parent link="LINK_3_visual_link"/>
    <child link="LINK_3_2"/>
    <axis xyz="0.00000 0.00000 1.00000"/>
  </joint>
  <link name="LINK_1_visual_link">
    <collision name="LINK_1_collision">
      <origin rpy="-0.00000 -0.00000 -0.00000" xyz="0.01035 0.00000 -0.03047"/>
      <geometry>
        <box size="0.07013 0.05471 0.06130"/>
      </geometry>
    </collision>
    <inertial>
      <inertia ixx="0.00004" ixy="0.00000" ixz="0.00001" iyy="0.00007" iyz="0.00000" izz="0.00005"/>
      <origin rpy="0.00000 0.00000 0.00000" xyz="0.00889 0.00002 -0.03303"/>
      <mass value="0.10000"/>
    </inertial>
    <visual name="LINK_1_visual">
      <origin rpy="0.00000 0.00000 -0.00000" xyz="0.00000 0.00000 0.00000"/>
      <material name="SILVER"/>
      <geometry>
        <mesh filename="file://$(find escalador_description_both)/meshes/ON-OFF-PAW-Alumínio_MEF.148.dae" scale="0.00100 0.00100 0.00100"/>
      </geometry>
    </visual>
  </link>
  <link name="LINK_2_visual_link">
    <collision name="LINK_2_collision">
      <origin rpy="-3.14159 -0.00000 0.00000" xyz="0.00000 -0.05789 0.02139"/>
      <geometry>
        <box size="0.03957 0.07267 0.07963"/>
      </geometry>
    </collision>
    <inertial>
      <inertia ixx="0.00011" ixy="0.00000" ixz="0.00000" iyy="0.00009" iyz="-0.00001" izz="0.00004"/>
      <origin rpy="0.00000 0.00000 0.00000" xyz="0.00003 -0.05457 0.02392"/>
      <mass value="0.10000"/>
    </inertial>
    <visual name="LINK_2_visual">
      <origin rpy="-0.00000 -0.00000 0.00000" xyz="-0.00000 0.00000 0.00000"/>
      <material name="ROBO"/>
      <geometry>
        <mesh filename="file://$(find escalador_description_both)/meshes/link_1_5.073.dae" scale="0.00100 0.00100 0.00100"/>
      </geometry>
    </visual>
  </link>
  <link name="LINK_3_2">
    <collision name="LINK_3_collision">
      <origin rpy="0.00000 0.00000 -0.50538" xyz="-0.05592 -0.09301 -0.00021"/>
      <geometry>
        <box size="0.03272 0.17192 0.03013"/>
      </geometry>
    </collision>
    <inertial>
      <inertia ixx="0.00034" ixy="0.00000" ixz="-0.00019" iyy="0.00045" iyz="0.00001" izz="0.00013"/>
      <origin rpy="0.00000 0.00000 0.00000" xyz="-0.04872 -0.07984 0.00133"/>
      <mass value="0.10000"/>
    </inertial>
    <visual name="LINK_3_visual">
      <origin rpy="-0.00000 0.00000 -0.00000" xyz="-0.00221 0.00059 0.00016"/>
      <material name="SILVER"/>
      <geometry>
        <mesh filename="file://$(find escalador_description_both)/meshes/link_2.dae" scale="0.00100 0.00100 0.00100"/>
      </geometry>
    </visual>
  </link>
  <link name="LINK_3_visual_link"/>
  <link name="LINK_4_visual_link">
    <collision name="LINK_4_collision">
      <origin rpy="-0.00000 0.00000 0.00000" xyz="0.04284 -0.07970 -0.02137"/>
      <geometry>
        <box size="0.03163 0.09384 0.03914"/>
      </geometry>
    </collision>
    <inertial>
      <inertia ixx="0.00013" ixy="0.00001" ixz="0.00006" iyy="0.00014" iyz="-0.00002" izz="0.00007"/>
      <origin rpy="0.00000 0.00000 0.00000" xyz="0.03805 -0.06580 -0.02396"/>
      <mass value="0.10000"/>
    </inertial>
    <visual name="LINK_4_visual">
      <origin rpy="-0.00000 -0.00000 -0.01635" xyz="-0.00000 -0.00000 0.00000"/>
      <material name="SILVER"/>
      <geometry>
        <mesh filename="file://$(find escalador_description_both)/meshes/link_3.076.dae" scale="0.00100 0.00100 0.00100"/>
      </geometry>
    </visual>
  </link>
  <link name="LINK_5_visual_link">
    <collision name="LINK_5_collision">
      <origin rpy="1.57080 0.01148 -0.00000" xyz="-0.00182 0.00039 -0.02867"/>
      <geometry>
        <box size="0.02969 0.06567 0.04125"/>
      </geometry>
    </collision>
    <inertial>
      <inertia ixx="0.00005" ixy="0.00000" ixz="0.00001" iyy="0.00005" iyz="-0.00000" izz="0.00003"/>
      <origin rpy="0.00000 0.00000 0.00000" xyz="0.00002 0.00023 -0.02469"/>
      <mass value="0.10000"/>
    </inertial>
    <visual name="LINK_5_visual">
      <origin rpy="1.57080 0.52299 -0.00000" xyz="0.00000 -0.00000 0.00000"/>
      <material name="ROBO"/>
      <geometry>
        <mesh filename="file://$(find escalador_description_both)/meshes/link_4.003.dae" scale="0.00100 0.00100 0.00100"/>
      </geometry>
    </visual>
  </link>
  <link name="LINK_6_visual_link">
    <collision name="LINK_6_collision">
      <origin rpy="-0.00000 -0.00000 -0.00000" xyz="0.00000 -0.06015 -0.03406"/>
      <geometry>
        <box size="0.03909 0.06148 0.06449"/>
      </geometry>
    </collision>
    <inertial>
      <inertia ixx="0.00011" ixy="0.00000" ixz="0.00000" iyy="0.00009" iyz="-0.00001" izz="0.00004"/>
      <origin rpy="0.00000 0.00000 0.00000" xyz="0.00004 -0.05486 -0.02428"/>
      <mass value="0.10000"/>
    </inertial>
    <visual name="LINK_6_visual">
      <origin rpy="-0.00000 -0.00000 -0.00000" xyz="0.00000 -0.00000 -0.00000"/>
      <material name="SILVER"/>
      <geometry>
        <mesh filename="file://$(find escalador_description_both)/meshes/link_1_5.003.dae" scale="0.00100 0.00100 0.00100"/>
      </geometry>
    </visual>
  </link>
  <link name="LINK_7_visual_link">
    <collision name="LINK_7_collision">
      <origin rpy="-0.00000 -0.00000 -0.00000" xyz="0.01285 -0.00000 -0.03189"/>
      <geometry>
        <box size="0.07521 0.04705 0.05898"/>
      </geometry>
    </collision>
    <inertial>
      <inertia ixx="0.00004" ixy="0.00000" ixz="0.00001" iyy="0.00007" iyz="0.00000" izz="0.00005"/>
      <origin rpy="0.00000 0.00000 0.00000" xyz="0.00889 0.00002 -0.03253"/>
      <mass value="0.10000"/>
    </inertial>
    <visual name="LINK_7_visual">
      <origin rpy="-0.00000 -0.00000 -0.00000" xyz="0.00000 -0.00000 -0.00000"/>
      <material name="ROBO"/>
      <geometry>
        <mesh filename="file://$(find escalador_description_both)/meshes/ON-OFF-PAW-Alumínio_MEF.050.dae" scale="0.00100 0.00100 0.00100"/>
      </geometry>
    </visual>
  </link>
  <material name="ROBO">
    <color rgba="0.80000 0.80000 0.80000 1.00000"/>
  </material>
  <material name="SILVER">
    <color rgba="0.80000 0.80000 0.80000 1.00000"/>
  </material>
</robot>
