<?xml version="1.0"?>
<robot xmlns:xacro="http://www.ros.org/wiki/xacro">


  <xacro:macro name="robot1" params="parent prefix *origin">
  <joint name="${prefix}base_joint" type="fixed">
    <xacro:insert_block name="origin" />
    <parent link="${parent}"/>
    <child link="${prefix}LINK_1" />
  </joint>

  <link name="${prefix}end-effector"/>
  <link name="${prefix}end-dummy"/>
  <joint name="dummy_joint" type="fixed">
    <limit upper="0" lower="0" effort="0" velocity="0"/>
    <origin rpy="0.0 3.14 0.0" xyz="0.0 0.0 0.000"/>
    <parent link="${prefix}end-effector"/>
    <child link="${prefix}end-dummy"/>
  </joint>
  <joint name="end_joint" type="fixed">
    <limit upper="0" lower="0" effort="0" velocity="0"/>
    <origin rpy="0.0 0.0 0.0" xyz="0.0 0.0 0.07100"/>
    <parent link="${prefix}LINK_7"/>
    <child link="${prefix}end-effector"/>
  </joint>

  <joint name="J1" type="revolute">
    <limit lower="-6.28000" upper="6.28000" effort="0.00000" velocity="0.00000"/>
    <origin rpy="-0.00000 -0.00000 3.14159" xyz="0.00000 -0.00000 0.07100"/>
    <parent link="${prefix}LINK_1"/>
    <child link="${prefix}LINK_2"/>
    <axis xyz="0.00000 0.00000 1.00000"/>
  </joint>
  <joint name="J2" type="revolute">
    <limit lower="-3.14000" upper="3.14000" effort="0.00000" velocity="0.00000"/>
    <origin rpy="-1.57080 0.00000 -3.14159" xyz="0.00000 0.00000 0.10900"/>
    <parent link="${prefix}LINK_2"/>
    <child link="${prefix}LINK_3"/>
    <axis xyz="0.00000 0.00000 1.00000"/>
  </joint>
  <joint name="J3" type="revolute">
    <limit lower="-3.14000" upper="3.14000" effort="0.00000" velocity="0.00000"/>
    <origin rpy="-0.00000 0.00000 0.00000" xyz="0.00000 -0.20000 0.00000"/>
    <parent link="${prefix}LINK_3"/>
    <child link="${prefix}LINK_4"/>
    <axis xyz="0.00000 0.00000 1.00000"/>
  </joint>
  <joint name="J4" type="revolute">
    <limit lower="-6.28000" upper="6.28000" effort="0.00000" velocity="0.00000"/>
    <origin rpy="1.57080 0.00000 0.00000" xyz="-0.00000 -0.13800 -0.00000"/>
    <parent link="${prefix}LINK_4"/>
    <child link="${prefix}LINK_5"/>
    <axis xyz="0.00000 0.00000 1.00000"/>
  </joint>
  <joint name="J5" type="revolute">
    <limit lower="-3.14000" upper="3.14000" effort="0.00000" velocity="0.00000"/>
    <origin rpy="-1.57080 0.00000 0.00000" xyz="0.00000 0.00000 0.06200"/>
    <parent link="${prefix}LINK_5"/>
    <child link="${prefix}LINK_6"/>
    <axis xyz="0.00000 0.00000 1.00000"/>
  </joint>
  <joint name="J6" type="revolute">
    <limit lower="-6.28000" upper="6.28000" effort="0.00000" velocity="0.00000"/>
    <origin rpy="1.57080 0.00000 0.00000" xyz="-0.00000 -0.10900 -0.00000"/>
    <parent link="${prefix}LINK_6"/>
    <child link="${prefix}LINK_7"/>
    <axis xyz="0.00000 0.00000 1.00000"/>
  </joint>
  <link name="${prefix}LINK_1">
    <collision name="LINK_1_collision">
      <origin rpy="0.00000 0.00000 0.00000" xyz="0.01529 -0.00000 0.03544"/>
      <geometry>
        <box size="0.07660 0.05818 0.06860"/>
      </geometry>
    </collision>
    <inertial>
      <origin xyz="-0.011218 -0.000000 0.018785" rpy="0 0 0"/>
      <mass value="0.375"/>
      <inertia ixx="0.000108994"
              ixy="-0.000000000" iyy="0.000198249"
              ixz="0.000016726" iyz="-0.000000000" izz="0.000200988" />
    </inertial>
    <visual name="LINK_1_visual">
      <origin rpy="0.00000 0.00000 -0.00000" xyz="-0.00000 -0.00000 0.00000"/>
      <material name="SILVER"/>
      <geometry>
        <mesh filename="file://$(find escalador_description_serial_1)/meshes/pata_1.dae" scale="0.00100 0.00100 0.00100"/>
      </geometry>
    </visual>
  </link>
  <link name="${prefix}LINK_2">
    <collision name="LINK_2_collision">
      <origin rpy="1.57080 -0.00000 0.00000" xyz="0.00000 0.00606 0.05094"/>
      <geometry>
        <box size="0.03961 0.06205 0.07038"/>
      </geometry>
    </collision>
    <inertial>
      <origin xyz="-0.000005 -0.008676 0.052092" rpy="0 0 0"/>
      <mass value="0.354"/>
      <inertia ixx="0.000223854"
              ixy="0.000000016" iyy="0.000146294"
              ixz="-0.000000107" iyz="-0.000034608" izz="0.000151022" />
    </inertial>
    <visual name="LINK_2_visual">
      <origin rpy="1.57080 0.00000 0.00000" xyz="0.00000 0.00000 0.00000"/>
      <material name="ROBO"/>
      <geometry>
        <mesh filename="file://$(find escalador_description_serial_1)/meshes/link_1_5.073.dae" scale="0.00100 0.00100 0.00100"/>
      </geometry>
    </visual>
  </link>
  <link name="${prefix}LINK_3">
    <collision name="LINK_3_collision">
      <origin rpy="0.00000 0.00000 3.13973" xyz="0.00013 -0.10084 0.00235"/>
      <geometry>
        <box size="0.03412 0.14763 0.05773"/>
      </geometry>
    </collision>
    <inertial>
      <origin xyz="-0.000017 -0.000742 0.101033" rpy="0 0 0"/>
      <mass value="0.477"/>
      <inertia ixx="0.002864655"
                ixy="-0.000000004" iyy="0.002867671"
                ixz="0.000000689" iyz="-0.000000419" izz="0.000140001" />
    </inertial>
    <visual name="LINK_3_visual">
      <origin rpy="0.00000 0.00000 -2.61870" xyz="-0.00000 0.00000 0.00000"/>
      <material name="SILVER"/>
      <geometry>
        <mesh filename="file://$(find escalador_description_serial_1)/meshes/link_2.dae" scale="0.00100 0.00100 0.00100"/>
      </geometry>
    </visual>
  </link>
  <link name="${prefix}LINK_4">
    <collision name="LINK_4_collision">
      <origin rpy="-0.00000 -0.00000 0.02402" xyz="-0.00013 -0.07778 0.00292"/>
      <geometry>
        <box size="0.02774 0.09960 0.05199"/>
      </geometry>
    </collision>
    <inertial>
        <origin xyz="0.000000 -0.009079 0.081987" rpy="0 0 0"/>
        <mass value="0.372"/>
        <inertia ixx="0.000135253"
                ixy="-0.000000000" iyy="0.000047636"
                ixz="-0.000000000" iyz="0.000000471" izz="0.000162513" />
    </inertial>
    <visual name="LINK_4_visual">
      <origin rpy="0.00000 0.00000 -0.52360" xyz="0.00000 0.00000 0.00000"/>
      <material name="SILVER"/>
      <geometry>
        <mesh filename="file://$(find escalador_description_serial_1)/meshes/link_3.076.dae" scale="0.00100 0.00100 0.00100"/>
      </geometry>
    </visual>
  </link>
  <link name="${prefix}LINK_5">
    <collision name="LINK_5_collision">
      <origin rpy="-1.57080 0.00509 0.00000" xyz="-0.00008 0.00105 0.03565"/>
      <geometry>
        <box size="0.03510 0.07617 0.03941"/>
      </geometry>
    </collision>
    <inertial>
        <origin xyz="0.000000 -0.001015 -0.021991" rpy="0 0 0"/>
        <mass value="0.202"/>
        <inertia ixx="0.000117912"
                ixy="-0.000000000" iyy="0.000105186"
                ixz="-0.000000000" iyz="0.000003166" izz="0.000048390" />
      </inertial>
    <visual name="LINK_5_visual">
      <origin rpy="-1.57080 -0.52299 0.00000" xyz="0.00000 -0.00000 -0.00000"/>
      <material name="ROBO"/>
      <geometry>
        <mesh filename="file://$(find escalador_description_serial_1)/meshes/link_4.003.dae" scale="0.00100 0.00100 0.00100"/>
      </geometry>
    </visual>
  </link>
  <link name="${prefix}LINK_6">
    <collision name="LINK_6_collision">
      <origin rpy="0.00000 0.00000 0.00000" xyz="-0.00004 -0.06277 -0.01268"/>
      <geometry>
        <box size="0.03018 0.06809 0.06256"/>
      </geometry>
    </collision>
    <inertial>
        <origin xyz="-0.000005 -0.008676 0.052092" rpy="0 0 0"/>
        <mass value="0.354"/>
        <inertia ixx="0.000223854"
                ixy="0.000000016" iyy="0.000146294"
                ixz="-0.000000107" iyz="-0.000034608" izz="0.000151022" />
    </inertial>
    <visual name="LINK_6_visual">
      <origin rpy="-0.00000 0.00000 0.00000" xyz="-0.00000 0.00000 0.00000"/>
      <material name="SILVER"/>
      <geometry>
        <mesh filename="file://$(find escalador_description_serial_1)/meshes/link_1_5.003.dae" scale="0.00100 0.00100 0.00100"/>
      </geometry>
    </visual>
  </link>
  <link name="${prefix}LINK_7">
    <collision name="LINK_7_collision">
      <origin rpy="3.14159 -0.00000 3.14159" xyz="-0.01628 0.00000 0.03790"/>
      <geometry>
        <box size="0.07085 0.05381 0.06345"/>
      </geometry>
    </collision>
    <inertial>
        <origin xyz="-0.011218 -0.000000 0.018785" rpy="0 0 0"/>
        <mass value="0.375"/>
        <inertia ixx="0.000108994"
                ixy="-0.000000000" iyy="0.000198249"
                ixz="0.000016726" iyz="-0.000000000" izz="0.000200988" />
    </inertial>
    <visual name="LINK_7_visual">
      <origin rpy="3.14159 -0.00000 3.14159" xyz="0.00000 0.00000 0.00000"/>
      <material name="ROBO"/>
      <geometry>
        <mesh filename="file://$(find escalador_description_serial_1)/meshes/pata_2.dae" scale="0.00100 0.00100 0.00100"/>
      </geometry>
    </visual>
  </link>
  
  <material name="ROBO">
    <color rgba="0.80000 0.80000 0.80000 1.00000"/>
  </material>
  <material name="SILVER">
    <color rgba="0.80000 0.80000 0.80000 1.00000"/>
  </material>
  </xacro:macro>
</robot>
